Workbook

Sheet Tableau de bord
A1: OptiTAB — Suivi des livres
A2: Mis à jour le 24 octobre 2026. Tous les chiffres se recalculent à partir des onglets.
A4: Matière | B4: Terminés | C4: En cours | D4: À faire | E4: Total | F4: % terminé | G4: Revérifiés par vous | H4: Pages livrées | I4: Exercices / activités livrés
A5: Mathématiques | B5: =COUNTIF(Mathématiques!$F$5:$F$200,"Terminé") | C5: =COUNTIF(Mathématiques!$F$5:$F$200,"En cours") | D5: =COUNTIF(Mathématiques!$F$5:$F$200,"À faire") | E5: =COUNTA(Mathématiques!$C$5:$C$200) | F5: =IF(E5=0,0,B5/E5) | G5: =COUNTIF(Mathématiques!$G$5:$G$200,"Oui") | H5: =SUMIF(Mathématiques!$F$5:$F$200,"Terminé",Mathématiques!$H$5:$H$200) | I5: =SUMIF(Mathématiques!$F$5:$F$200,"Terminé",Mathématiques!$J$5:$J$200)
A6: Physique-chimie | B6: =COUNTIF('Physique-chimie'!$F$5:$F$200,"Terminé") | C6: =COUNTIF('Physique-chimie'!$F$5:$F$200,"En cours") | D6: =COUNTIF('Physique-chimie'!$F$5:$F$200,"À faire") | E6: =COUNTA('Physique-chimie'!$C$5:$C$200) | F6: =IF(E6=0,0,B6/E6) | G6: =COUNTIF('Physique-chimie'!$G$5:$G$200,"Oui") | H6: =SUMIF('Physique-chimie'!$F$5:$F$200,"Terminé",'Physique-chimie'!$H$5:$H$200) | I6: =SUMIF('Physique-chimie'!$F$5:$F$200,"Terminé",'Physique-chimie'!$J$5:$J$200)
A7: Total | B7: =SUM(B5:B6) | C7: =SUM(C5:C6) | D7: =SUM(D5:D6) | E7: =SUM(E5:E6) | F7: =IF(E7=0,0,B7/E7) | G7: =SUM(G5:G6) | H7: =SUM(H5:H6) | I7: =SUM(I5:I6)
A10: Mathématiques par catégorie
A11: Catégorie | B11: Terminés | C11: En cours | D11: À faire | E11: Total
A12: Maternelle | B12: =COUNTIFS(Mathématiques!$B$5:$B$200,$A12,Mathématiques!$F$5:$F$200,"Terminé") | C12: =COUNTIFS(Mathématiques!$B$5:$B$200,$A12,Mathématiques!$F$5:$F$200,"En cours") | D12: =COUNTIFS(Mathématiques!$B$5:$B$200,$A12,Mathématiques!$F$5:$F$200,"À faire") | E12: =COUNTIF(Mathématiques!$B$5:$B$200,$A12)
A13: École élémentaire | B13: =COUNTIFS(Mathématiques!$B$5:$B$200,$A13,Mathématiques!$F$5:$F$200,"Terminé") | C13: =COUNTIFS(Mathématiques!$B$5:$B$200,$A13,Mathématiques!$F$5:$F$200,"En cours") | D13: =COUNTIFS(Mathématiques!$B$5:$B$200,$A13,Mathématiques!$F$5:$F$200,"À faire") | E13: =COUNTIF(Mathématiques!$B$5:$B$200,$A13)
A14: Collège | B14: =COUNTIFS(Mathématiques!$B$5:$B$200,$A14,Mathématiques!$F$5:$F$200,"Terminé") | C14: =COUNTIFS(Mathématiques!$B$5:$B$200,$A14,Mathématiques!$F$5:$F$200,"En cours") | D14: =COUNTIFS(Mathématiques!$B$5:$B$200,$A14,Mathématiques!$F$5:$F$200,"À faire") | E14: =COUNTIF(Mathématiques!$B$5:$B$200,$A14)
A15: Lycée général | B15: =COUNTIFS(Mathématiques!$B$5:$B$200,$A15,Mathématiques!$F$5:$F$200,"Terminé") | C15: =COUNTIFS(Mathématiques!$B$5:$B$200,$A15,Mathématiques!$F$5:$F$200,"En cours") | D15: =COUNTIFS(Mathématiques!$B$5:$B$200,$A15,Mathématiques!$F$5:$F$200,"À faire") | E15: =COUNTIF(Mathématiques!$B$5:$B$200,$A15)
A16: Prépa scientifique 1re année | B16: =COUNTIFS(Mathématiques!$B$5:$B$200,$A16,Mathématiques!$F$5:$F$200,"Terminé") | C16: =COUNTIFS(Mathématiques!$B$5:$B$200,$A16,Mathématiques!$F$5:$F$200,"En cours") | D16: =COUNTIFS(Mathématiques!$B$5:$B$200,$A16,Mathématiques!$F$5:$F$200,"À faire") | E16: =COUNTIF(Mathématiques!$B$5:$B$200,$A16)
A17: Prépa scientifique 2e année | B17: =COUNTIFS(Mathématiques!$B$5:$B$200,$A17,Mathématiques!$F$5:$F$200,"Terminé") | C17: =COUNTIFS(Mathématiques!$B$5:$B$200,$A17,Mathématiques!$F$5:$F$200,"En cours") | D17: =COUNTIFS(Mathématiques!$B$5:$B$200,$A17,Mathématiques!$F$5:$F$200,"À faire") | E17: =COUNTIF(Mathématiques!$B$5:$B$200,$A17)
A18: Prépa économique (ECG) | B18: =COUNTIFS(Mathématiques!$B$5:$B$200,$A18,Mathématiques!$F$5:$F$200,"Terminé") | C18: =COUNTIFS(Mathématiques!$B$5:$B$200,$A18,Mathématiques!$F$5:$F$200,"En cours") | D18: =COUNTIFS(Mathématiques!$B$5:$B$200,$A18,Mathématiques!$F$5:$F$200,"À faire") | E18: =COUNTIF(Mathématiques!$B$5:$B$200,$A18)
A19: Concours de l’enseignement | B19: =COUNTIFS(Mathématiques!$B$5:$B$200,$A19,Mathématiques!$F$5:$F$200,"Terminé") | C19: =COUNTIFS(Mathématiques!$B$5:$B$200,$A19,Mathématiques!$F$5:$F$200,"En cours") | D19: =COUNTIFS(Mathématiques!$B$5:$B$200,$A19,Mathématiques!$F$5:$F$200,"À faire") | E19: =COUNTIF(Mathématiques!$B$5:$B$200,$A19)
A20: Concours post-bac | B20: =COUNTIFS(Mathématiques!$B$5:$B$200,$A20,Mathématiques!$F$5:$F$200,"Terminé") | C20: =COUNTIFS(Mathématiques!$B$5:$B$200,$A20,Mathématiques!$F$5:$F$200,"En cours") | D20: =COUNTIFS(Mathématiques!$B$5:$B$200,$A20,Mathématiques!$F$5:$F$200,"À faire") | E20: =COUNTIF(Mathématiques!$B$5:$B$200,$A20)
A21: Concours CPGE ingénieurs et ENS | B21: =COUNTIFS(Mathématiques!$B$5:$B$200,$A21,Mathématiques!$F$5:$F$200,"Terminé") | C21: =COUNTIFS(Mathématiques!$B$5:$B$200,$A21,Mathématiques!$F$5:$F$200,"En cours") | D21: =COUNTIFS(Mathématiques!$B$5:$B$200,$A21,Mathématiques!$F$5:$F$200,"À faire") | E21: =COUNTIF(Mathématiques!$B$5:$B$200,$A21)
A22: Concours CPGE commerce | B22: =COUNTIFS(Mathématiques!$B$5:$B$200,$A22,Mathématiques!$F$5:$F$200,"Terminé") | C22: =COUNTIFS(Mathématiques!$B$5:$B$200,$A22,Mathématiques!$F$5:$F$200,"En cours") | D22: =COUNTIFS(Mathématiques!$B$5:$B$200,$A22,Mathématiques!$F$5:$F$200,"À faire") | E22: =COUNTIF(Mathématiques!$B$5:$B$200,$A22)
A23: Concours lycéens | B23: =COUNTIFS(Mathématiques!$B$5:$B$200,$A23,Mathématiques!$F$5:$F$200,"Terminé") | C23: =COUNTIFS(Mathématiques!$B$5:$B$200,$A23,Mathématiques!$F$5:$F$200,"En cours") | D23: =COUNTIFS(Mathématiques!$B$5:$B$200,$A23,Mathématiques!$F$5:$F$200,"À faire") | E23: =COUNTIF(Mathématiques!$B$5:$B$200,$A23)
A26: Physique-chimie par catégorie
A27: Catégorie | B27: Terminés | C27: En cours | D27: À faire | E27: Total
A28: Collège | B28: =COUNTIFS('Physique-chimie'!$B$5:$B$200,$A28,'Physique-chimie'!$F$5:$F$200,"Terminé") | C28: =COUNTIFS('Physique-chimie'!$B$5:$B$200,$A28,'Physique-chimie'!$F$5:$F$200,"En cours") | D28: =COUNTIFS('Physique-chimie'!$B$5:$B$200,$A28,'Physique-chimie'!$F$5:$F$200,"À faire") | E28: =COUNTIF('Physique-chimie'!$B$5:$B$200,$A28)
A29: Lycée général | B29: =COUNTIFS('Physique-chimie'!$B$5:$B$200,$A29,'Physique-chimie'!$F$5:$F$200,"Terminé") | C29: =COUNTIFS('Physique-chimie'!$B$5:$B$200,$A29,'Physique-chimie'!$F$5:$F$200,"En cours") | D29: =COUNTIFS('Physique-chimie'!$B$5:$B$200,$A29,'Physique-chimie'!$F$5:$F$200,"À faire") | E29: =COUNTIF('Physique-chimie'!$B$5:$B$200,$A29)
A30: Prépa scientifique | B30: =COUNTIFS('Physique-chimie'!$B$5:$B$200,$A30,'Physique-chimie'!$F$5:$F$200,"Terminé") | C30: =COUNTIFS('Physique-chimie'!$B$5:$B$200,$A30,'Physique-chimie'!$F$5:$F$200,"En cours") | D30: =COUNTIFS('Physique-chimie'!$B$5:$B$200,$A30,'Physique-chimie'!$F$5:$F$200,"À faire") | E30: =COUNTIF('Physique-chimie'!$B$5:$B$200,$A30)
A31: Concours de l’enseignement | B31: =COUNTIFS('Physique-chimie'!$B$5:$B$200,$A31,'Physique-chimie'!$F$5:$F$200,"Terminé") | C31: =COUNTIFS('Physique-chimie'!$B$5:$B$200,$A31,'Physique-chimie'!$F$5:$F$200,"En cours") | D31: =COUNTIFS('Physique-chimie'!$B$5:$B$200,$A31,'Physique-chimie'!$F$5:$F$200,"À faire") | E31: =COUNTIF('Physique-chimie'!$B$5:$B$200,$A31)
A32: Concours CPGE ingénieurs et ENS | B32: =COUNTIFS('Physique-chimie'!$B$5:$B$200,$A32,'Physique-chimie'!$F$5:$F$200,"Terminé") | C32: =COUNTIFS('Physique-chimie'!$B$5:$B$200,$A32,'Physique-chimie'!$F$5:$F$200,"En cours") | D32: =COUNTIFS('Physique-chimie'!$B$5:$B$200,$A32,'Physique-chimie'!$F$5:$F$200,"À faire") | E32: =COUNTIF('Physique-chimie'!$B$5:$B$200,$A32)
A35: Mises à jour et décisions
A36: Mises à jour faites (programmes, correctif) | B36: =COUNTA('Mises à jour'!$B$5:$B$200)
A37: Nouvelles éditions livrées | B37: =COUNTIF('Mises à jour'!$C$5:$C$200,"Nouvelle édition")
A38: Décisions en attente | B38: =COUNTIF('À décider'!$G$5:$G$200,"À trancher")
A39: dont priorité haute | B39: =COUNTIFS('À décider'!$G$5:$G$200,"À trancher",'À décider'!$E$5:$E$200,"Haute")
A42: Mode d’emploi
A43: Statuts : Terminé (vert) = PDF final livré dans output et sur le Bureau ; En cours (orange) ; À faire (gris).
A44: Cellules jaunes = à remplir par vous : « Revérifié par vous » (Oui / Non) dans les onglets de matière, « Votre réponse » et « Statut » dans l’onglet À décider.
A45: Ce tableau de bord se met à jour tout seul quand vous changez un statut ou passez un livre à « Oui ».
A46: Pour ajouter un livre, écrivez-le à la fin de l’onglet de sa matière avec la même catégorie : il sera compté automatiquement.

Sheet Mathématiques
A1: Mathématiques — tous les livres
A2: Statut au 23/10/2026. Colonne jaune « Revérifié par vous » : à remplir après votre relecture (Oui / Non).
A4: N° | B4: Catégorie | C4: Livre | D4: Édition | E4: Programme de référence | F4: Statut | G4: Revérifié par vous | H4: Pages | I4: Chapitres / parties | J4: Exercices / activités | K4: Livré le | L4: Dossier source | M4: Fichier PDF | N4: Remarques
A5: 1 | B5: Maternelle | C5: Petite Section (PS) | D5: 2026-2027 | E5: Programme maternelle, BO n°41 du 31/10/2024 (consolidé BO n°19 du 07/05/2026) | F5: Terminé | G5: Non | H5: 67 | I5: 7 | J5: 40 | K5: 46318 | L5: livre-maternelle/ (ps.py) | M5: OptiTAB - Mathématiques - Petite section (PS) - Cahier d’activités.pdf | N5: Cahier d’activités illustré (40 activités, 7 parties) + guide de l’adulte avec réponses
A6: 2 | B6: Maternelle | C6: Moyenne Section (MS) | D6: 2026-2027 | E6: Programme maternelle, BO n°41 du 31/10/2024 (consolidé BO n°19 du 07/05/2026) | F6: Terminé | G6: Non | H6: 85 | I6: 9 | J6: 53 | K6: 46318 | L6: livre-maternelle/ (ms.py) | M6: OptiTAB - Mathématiques - Moyenne section (MS) - Cahier d’activités.pdf | N6: Cahier d’activités illustré (53 activités, 9 parties) + guide de l’adulte avec réponses
A7: 3 | B7: Maternelle | C7: Grande Section (GS) | D7: 2026-2027 | E7: Programme maternelle, BO n°41 du 31/10/2024 (consolidé BO n°19 du 07/05/2026) | F7: Terminé | G7: Non | H7: 88 | I7: 9 | J7: 56 | K7: 46318 | L7: livre-maternelle/ (gs.py) | M7: OptiTAB - Mathématiques - Grande section (GS) - Cahier d’activités.pdf | N7: Cahier d’activités illustré (56 activités, 9 parties) + guide de l’adulte avec réponses
A8: 4 | B8: École élémentaire | C8: CP | D8: 2026-2027 | E8: Programme du cycle 2, BO du 31/10/2024 | F8: Terminé | G8: Non | H8: 262 | I8: 30 | J8: 270 | K8: 46318 | L8: livre-cp/ | M8: OptiTAB - Mathématiques - CP - Manuel complet.pdf | N8: 5 bilans, 360 problèmes oraux, matériel à photocopier
A9: 5 | B9: École élémentaire | C9: CE1 | D9: 2026-2027 | E9: Programme du cycle 2, BO du 31/10/2024 | F9: Terminé | G9: Non | H9: 277 | I9: 32 | J9: 288 | K9: 46318 | L9: livre-ce1/ | M9: OptiTAB - Mathématiques - CE1 - Manuel complet.pdf | N9: 5 bilans, 360 problèmes oraux, fiches de fluence
A10: 6 | B10: École élémentaire | C10: CE2 | D10: 2026-2027 | E10: Programme du cycle 2, BO du 31/10/2024 | F10: Terminé | G10: Non | H10: 311 | I10: 36 | J10: 324 | K10: 46318 | L10: livre-ce2/ | M10: OptiTAB - Mathématiques - CE2 - Manuel complet.pdf | N10: 5 bilans, 360 problèmes oraux, 6 pages de méthode
A11: 7 | B11: École élémentaire | C11: CM1 | D11: 2026-2027 | E11: Programmes 2025, BO n°16 du 17/04/2025 | F11: Terminé | G11: Non | H11: 328 | I11: 21 | J11: 315 | K11: 46318 | L11: livre-cm1/ | M11: OptiTAB - Mathématiques - CM1 - Manuel complet.pdf | N11: 21 défis, 2 bilans
A12: 8 | B12: École élémentaire | C12: CM2 | D12: 2026-2027 | E12: Programmes 2025, BO n°16 du 17/04/2025 | F12: Terminé | G12: Non | H12: 319 | I12: 21 | J12: 315 | K12: 46318 | L12: livre-cm2/ | M12: OptiTAB - Mathématiques - CM2 - Manuel complet.pdf | N12: 21 défis, 2 bilans
A13: 9 | B13: Collège | C13: Sixième (6e) | D13: 2026-2027 | E13: Programme 2025 du cycle 3 | F13: Terminé | G13: Non | H13: 342 | I13: 21 | J13: 315 | K13: 46318 | L13: livre-sixieme/ | M13: OptiTAB - Mathématiques - Sixième (6e) - Manuel complet.pdf | N13: 84 sections de cours, 21 défis, 2 bilans
A14: 10 | B14: Collège | C14: Cinquième (5e) | D14: 2026-2027 | E14: Programme cycle 4 2026, BO n°10 du 05/03/2026 | F14: Terminé | G14: Non | H14: 328 | I14: 20 | J14: 300 | K14: 46317 | L14: livre-cinquieme/ | M14: OptiTAB - Mathématiques - Cinquième (5e) - Manuel complet.pdf | N14: Audité le 23/10/2026 : 117 attendus vérifiés, 14 corrigés, PDF relivré
A15: 11 | B15: Collège | C15: Quatrième (4e) | D15: 2026-2027 | E15: Ancien programme (le programme 2026 s’applique en 4e à la rentrée 2027) | F15: Terminé | G15: Non | H15: 315 | I15: 18 | J15: 270 | K15: 46317 | L15: livre-quatrieme/ | M15: OptiTAB - Mathématiques - Quatrième (4e) - Manuel complet.pdf | N15: Nouvelle édition programme 2027 livrée le 23/10/2026 (onglet Mises à jour)
A16: 12 | B16: Collège | C16: Troisième (3e) - Brevet 2027 | D16: 2026-2027 | E16: Ancien programme (le programme 2026 s’applique en 3e à la rentrée 2028) | F16: Terminé | G16: Non | H16: 313 | I16: 18 | J16: 270 | K16: 46317 | L16: livre-troisieme/ | M16: OptiTAB - Mathématiques - Troisième (3e) - Brevet 2027 - Manuel complet.pdf | N16: Correctif du 23/10/2026 (signes % au chapitre 6). Nouvelle édition programme 2028 livrée
... A19: 15 | B19: Lycée général | C19: Terminale spécialité | D19: 2026-2027 | E19: Programme 2019 (en vigueur en 2026-2027) | F19: Terminé | G19: Non | H19: 374 | I19: 22 | J19: 274 | K19: 46316 | L19: livre-terminale/ | M19: OptiTAB - Mathématiques - Terminale spécialité - Manuel complet.pdf | N19: 10 sujets type bac corrigés. ISBN à compléter. Nouvelle édition programme 2027 livrée
A20: 16 | B20: Lycée général | C20: Maths expertes (option Terminale) | F20: À faire | G20: Non
A21: 17 | B21: Lycée général | C21: Maths complémentaires (option Terminale) | F21: À faire | G21: Non
A22: 18 | B22: Prépa scientifique 1re année | C22: MPSI | D22: 2026-2027 | E22: Arrêté du 05/01/2021, BO spécial n°1 du 11/02/2021 (annexe MPSI/MP2I) | F22: Terminé | G22: Non | H22: 552 | I22: 20 | J22: 500 | K22: 24/10/2026 | L22: livre-mpsi/ | M22: OptiTAB - Mathématiques - MPSI - Manuel complet.pdf | N22: 25 exercices par chapitre (Applications, Entraînement, Approfondissement, Défi) ; partie Évaluations : 6 DS, 4 DM, 2 examens, 4 sujets type concours (CCINP, Mines-Ponts, Centrale-Supélec, X-ENS), corrigés avec barème ; ~62 900 vérifications Python. ISBN à compléter.
A23: 19 | B23: Prépa scientifique 1re année | C23: MP2I | F23: À faire | G23: Non
A24: 20 | B24: Prépa scientifique 1re année | C24: PCSI | F24: À faire | G24: Non
A25: 21 | B25: Prépa scientifique 1re année | C25: PTSI | F25: À faire | G25: Non
A26: 22 | B26: Prépa scientifique 1re année | C26: BCPST 1 | F26: À faire | G26: Non
A27: 23 | B27: Prépa scientifique 2e année | C27: MP | F27: À faire | G27: Non
A28: 24 | B28: Prépa scientifique 2e année | C28: MPI | F28: À faire | G28: Non
A29: 25 | B29: Prépa scientifique 2e année | C29: PC | F29: À faire | G29: Non
A30: 26 | B30: Prépa scientifique 2e année | C30: PSI | F30: À faire | G30: Non
A31: 27 | B31: Prépa scientifique 2e année | C31: PT | F31: À faire | G31: Non
A32: 28 | B32: Prépa scientifique 2e année | C32: BCPST 2 | F32: À faire | G32: Non
A33: 29 | B33: Prépa économique (ECG) | C33: Maths approfondies — ECG 1 | F33: À faire | G33: Non
A34: 30 | B34: Prépa économique (ECG) | C34: Maths appliquées — ECG 1 | F34: À faire | G34: Non
... A38: 34 | B38: Concours de l’enseignement | C38: CAPES | F38: À faire | G38: Non
A39: 35 | B39: Concours de l’enseignement | C39: CAPLP maths-sciences | F39: À faire | G39: Non | N39: Couvre maths + physique-chimie (lycée professionnel)
A40: 36 | B40: Concours de l’enseignement | C40: Agrégation externe | F40: À faire | G40: Non
A41: 37 | B41: Concours de l’enseignement | C41: Agrégation interne | F41: À faire | G41: Non
A42: 38 | B42: Concours post-bac | C42: Ingénieurs post-bac (Avenir, Puissance Alpha, GEIPI-Polytech) | F42: À faire | G42: Non
A43: 39 | B43: Concours post-bac | C43: Commerce post-bac (Sésame, Accès) | F43: À faire | G43: Non
A44: 40 | B44: Concours CPGE ingénieurs et ENS | C44: X-ENS | F44: À faire | G44: Non | N44: Polytechnique + ENS
A45: 41 | B45: Concours CPGE ingénieurs et ENS | C45: Mines-Ponts | F45: À faire | G45: Non
A46: 42 | B46: Concours CPGE ingénieurs et ENS | C46: Centrale-Supélec | F46: À faire | G46: Non
...

Sheet Physique-chimie
A1: Physique-chimie — tous les livres
A2: Statut au 23/10/2026. Colonne jaune « Revérifié par vous » : à remplir après votre relecture (Oui / Non).
A4: N° | B4: Catégorie | C4: Livre | D4: Édition | E4: Programme de référence | F4: Statut | G4: Revérifié par vous | H4: Pages | I4: Chapitres / parties | J4: Exercices / activités | K4: Livré le | L4: Dossier source | M4: Fichier PDF | N4: Remarques
A5: 1 | B5: Collège | C5: Cinquième (5e) | D5: 2026-2027 | E5: Programme du cycle 4 | F5: En cours | G5: Non | I5: 20 | J5: 300 | L5: livre-pc-cinquieme/ | M5: OptiTAB - Physique-chimie - Cinquième (5e) - Manuel complet.pdf | N5: Manuel complet en cours de mise en page ; une version de 301 pages est dans output, pas encore sur le Bureau
A6: 2 | B6: Collège | C6: Quatrième (4e) | F6: À faire | G6: Non
A7: 3 | B7: Collège | C7: Troisième (3e) | F7: À faire | G7: Non
A8: 4 | B8: Lycée général | C8: Seconde | F8: À faire | G8: Non | N8: Vérifier d’abord si le BO du 02/04/2026 modifie le programme
A9: 5 | B9: Lycée général | C9: Première spécialité | D9: 2026-2027 | E9: Programme 2019 (BO spécial n°1 du 22/01/2019), inchangé en 2026 | F9: En cours | G9: Non | H9: 295 | I9: 21 | J9: 315 | L9: livre-pc-premiere/ | N9: Chapitres 1 à 12 terminés le 24/10/2026 (chimie 1 à 10, champs, fluides au repos) : 180 exercices, corrigés illustrés et pédagogiques, défis D01 à D12, calculs vérifiés (295 pages, aperçu livre-pc-premiere/main.pdf) ; suite deux chapitres à la fois après validation
A10: 6 | B10: Lycée général | C10: Terminale spécialité | D10: 2026-2027 | E10: Programme 2019 (BO spécial n°8 du 25/07/2019) ; épreuve 2027 : note du 11/09/2026 | F10: Terminé | G10: Non | H10: 701 | I10: 27 | J10: 405 | K10: 46318 | L10: livre-pc-terminale/ | M10: OptiTAB - Physique-chimie - Terminale spécialité - Manuel complet.pdf | N10: Livré le 23/10/2026 : 27 chapitres (405 exercices corrigés), 27 défis, 6 sujets type bac corrigés avec barèmes, guides de l’épreuve et de l’ECE, fiches expérimentales, données utiles et repères du programme ; toutes les valeurs vérifiées par programme
A11: 7 | B11: Prépa scientifique | C11: MPSI | F11: À faire | G11: Non
A12: 8 | B12: Prépa scientifique | C12: PCSI | F12: À faire | G12: Non
A13: 9 | B13: Prépa scientifique | C13: PTSI | F13: À faire | G13: Non
A14: 10 | B14: Prépa scientifique | C14: BCPST 1 | F14: À faire | G14: Non
A15: 11 | B15: Prépa scientifique | C15: Physique MP / MPI | F15: À faire | G15: Non
A16: 12 | B16: Prépa scientifique | C16: PC | F16: À faire | G16: Non
A17: 13 | B17: Prépa scientifique | C17: Physique PSI | F17: À faire | G17: Non
A18: 14 | B18: Prépa scientifique | C18: Physique PT | F18: À faire | G18: Non
A19: 15 | B19: Prépa scientifique | C19: BCPST 2 | F19: À faire | G19: Non
A20: 16 | B20: Concours de l’enseignement | C20: CAPES physique-chimie | F20: À faire | G20: Non
A21: 17 | B21: Concours de l’enseignement | C21: Agrégation externe — physique | F21: À faire | G21: Non
A22: 18 | B22: Concours de l’enseignement | C22: Agrégation externe — chimie | F22: À faire | G22: Non
... A28: 24 | B28: Concours CPGE ingénieurs et ENS | C28: Agro-Véto & G2E (BCPST) | F28: À faire | G28: Non
A30: Sources : SUIVI-LIVRES.md et fichiers des livres (README, plans, PDF livrés), relevés le 23/10/2026. Les PDF sont dans output/<Matière>/ et sur le Bureau, dossier « Livres OptiTAB - Lycée ».

Sheet Mises à jour
A1: Mises à jour pour les nouveaux programmes
A2: Faites le 23/10/2026. Les anciennes versions remplacées sont gardées dans archives/anciennes-versions/.
A4: N° | B4: Livre | C4: Type | D4: Programme | E4: Applicable | F4: Fait le | G4: Pages avant | H4: Pages après | I4: Écart de pages | J4: Ce qui a changé | K4: Dossier | L4: Fichier PDF | M4: Ancienne version / édition actuelle
A5: 1 | B5: Cinquième (5e) | C5: Audit de conformité | D5: Programme cycle 4 2026 (BO n°10 du 05/03/2026) | E5: Rentrée 2026 | F5: 46318 | G5: 328 | H5: 328 | I5: =H5-G5 | J5: 117 attendus vérifiés un par un, 14 corrigés (valeur absolue, échelle de probabilité, démonstrations, perspective…) | K5: livre-cinquieme/ | L5: OptiTAB - Mathématiques - Cinquième (5e) - Manuel complet.pdf | M5: optitab-cinquieme-complet-avant-audit-2026-10-23.pdf
A6: 2 | B6: Seconde | C6: Audit de conformité | D6: BO n°14 du 02/04/2026 (NOR MENE2602914A) | E6: Rentrée 2026 | F6: 46318 | G6: 279 | H6: 285 | I6: =H6-G6 | J6: 178 attendus vérifiés ; 40 questions flash d’automatismes ; défaut d’affichage « oprule » des tableaux corrigé | K6: livre-seconde/ | L6: OptiTAB - Mathématiques - Seconde générale et technologique - Manuel complet.pdf | M6: optitab-seconde-complet-avant-audit-2026-10-23.pdf
A7: 3 | B7: Première spécialité | C7: Audit de conformité + épreuve anticipée | D7: BO n°14 du 02/04/2026 (NOR MENE2602917A) ; note du 11/09/2026 (NOR MENE2622640N) | E7: Rentrée 2026 (bac 2028) | F7: 46318 | G7: 317 | H7: 319 | I7: =H7-G7 | J7: Sujets blancs refaits au format officiel (2 h, sans calculatrice, 6 + 14 points) ; guide de l’épreuve complété | K7: livre-premiere/ | L7: OptiTAB - Mathématiques - Première spécialité - Manuel complet.pdf | M7: optitab-premiere-complet-avant-audit-2026-10-23.pdf
A8: 4 | B8: Quatrième (4e) | C8: Nouvelle édition | D8: Programme cycle 4 2026 (BO n°10 du 05/03/2026) | E8: Rentrée 2027 | F8: 46318 | G8: 315 | H8: 319 | I8: =H8-G8 | J8: 3 nouveaux chapitres (droites remarquables, droite des milieux, triangle rectangle et cercle) ; Thalès, cosinus, puissances négatives passent en 3e | K8: livre-quatrieme-2027/ | L8: OptiTAB - Mathématiques - Quatrième (4e) - Programme 2027 - Manuel complet.pdf | M8: Édition 2026-2027 conservée
A9: 5 | B9: Troisième (3e) | C9: Nouvelle édition | D9: Programme cycle 4 2026 (BO n°10 du 05/03/2026) ; brevet : note du 11/09/2026 | E9: Rentrée 2028 (brevet 2029) | F9: 46318 | G9: 313 | H9: 316 | I9: =H9-G9 | J9: Nouveau chapitre « Translations et vecteurs », 74 exercices nouveaux, 2 brevets blancs refaits ; homothéties et triangles semblables retirés | K9: livre-troisieme-2028/ | L9: OptiTAB - Mathématiques - Troisième (3e) - Programme 2028 - Brevet 2029 - Manuel complet.pdf | M9: Édition 2026-2027 conservée
A10: 6 | B10: Terminale spécialité | C10: Nouvelle édition | D10: BO n°14 du 02/04/2026 (NOR MENE2602919A) ; épreuve : NOR MENE2622642N | E10: Rentrée 2027 (bac 2028) | F10: 46318 | G10: 374 | H10: 398 | I10: =H10-G10 | J10: 23 chapitres : sinus et cosinus, plans perpendiculaires, nouveau chapitre « Ensembles, logique et raisonnement » ; 2 points de langue au bac | K10: livre-terminale-2027/ | L10: OptiTAB - Mathématiques - Terminale spécialité - Programme 2027 - Manuel complet.pdf | M10: Édition 2026-2027 conservée
A11: 7 | B11: Troisième (3e) - Brevet 2027 | C11: Correctif | D11: — | E11: — | F11: 46318 | G11: 313 | H11: 313 | I11: =H11-G11 | J11: 15 signes % qui coupaient des énoncés et corrigés au chapitre 6 ; garde-fou ajouté à la fabrication | K11: livre-troisieme/ | L11: OptiTAB - Mathématiques - Troisième (3e) - Brevet 2027 - Manuel complet.pdf | M11: optitab-troisieme-brevet-avant-correctif-2026-10-23.pdf

Sheet À décider
A1: Décisions en attente
A2: Colonnes jaunes à remplir : votre réponse, puis passez le statut à « Réglé ».
A4: N° | B4: Livre | C4: Question | D4: Situation actuelle | E4: Priorité | F4: Votre réponse | G4: Statut
A5: 1 | B5: Physique-chimie Terminale | C5: Finir la livraison : copier le PDF final (703 pages) dans output et sur le Bureau ? | D5: Fait le 23/10/2026 : PDF final (701 pages) livré dans output et sur le Bureau | E5: Haute | G5: Réglé
A6: 2 | B6: Terminale spécialité | C6: ISBN et dépôt légal de l’édition 2026-2027 | D6: Page ISBN/éditeur à compléter (aucun ISBN inventé) | E6: Moyenne | G6: À trancher
A7: 3 | B7: Terminale spécialité — édition 2027 | C7: Nouvel ISBN pour l’édition 2027-2028 | D7: À fournir | E7: Moyenne | G7: À trancher
A8: 4 | B8: Terminale spécialité — édition 2027 | C8: Barème des sujets : 18 points d’exercices + 2 points de langue ? | D8: Choix OptiTAB, présenté comme tel dans le livre | E8: Basse | G8: À trancher
A9: 5 | B9: Première spécialité | C9: Barème détaillé des sujets blancs (0,5 point par automatisme, 7 points par exercice) | D9: Choix pédagogique ; l’officiel fixe seulement 6 + 14 points | E9: Basse | G9: À trancher
A10: 6 | B10: Troisième — édition 2028 | C10: Format du brevet 2029 | D10: Format en vigueur depuis 2027 retenu ; à revérifier quand le texte 2029 paraîtra | E10: Moyenne | G10: À trancher
A11: 7 | B11: Troisième — édition 2028 | C11: Barème des brevets blancs (12 automatismes à 0,5 point, 4 problèmes à 3,5 points) | D11: Choix éditorial | E11: Basse | G11: À trancher
A12: 8 | B12: Troisième — édition 2028 | C12: Chapitre 7 « Grandeurs quotients et conversions » (notions de 4e) : garder en révision ? | D12: Gardé et signalé comme révision | E12: Basse | G12: À trancher
A13: 9 | B13: Quatrième — édition 2027 | C13: Cas d’égalité des triangles et agrandissements-réductions : remettre en option « pour aller plus loin » ? | D13: Retirés entièrement | E13: Basse | G13: À trancher
A14: 10 | B14: Quatrième — édition 2027 | C14: Notation de l’évènement contraire | D14: Ā (le programme n’impose pas de notation) | E14: Basse | G14: À trancher
A15: 11 | B15: Quatrième — édition 2027 | C15: Médiane d’une série d’effectif pair | D15: Toute valeur entre les deux valeurs centrales, on retient leur moyenne | E15: Basse | G15: À trancher
A16: 12 | B16: Cinquième (5e) | C16: Ajouter de courts encadrés historiques (Brahmagupta, Al-Khwarizmi, Nightingale…) ? | D16: Non traités (prolongements facultatifs du programme) | E16: Basse | G16: À trancher
... A26: 22 | B26: Python — Volume 1 « First Steps » | C26: ISBN, dépôt légal et prix de vente du volume 1 Python | D26: « Forthcoming » sur la page de titre et en 4e de couverture | E26: Moyenne | G26: À trancher

Sheet Programmes officiels
A1: Programmes officiels de référence
A2: Textes vérifiés sur education.gouv.fr et eduscol.education.gouv.fr (octobre 2026).
A4: Niveau | B4: Texte | C4: Référence | D4: Application | E4: Livres OptiTAB
A5: Maternelle (PS, MS, GS) | B5: Programme de l’école maternelle | C5: BO n°41 du 31/10/2024 ; version consolidée BO n°19 du 07/05/2026 | D5: Rentrée 2025 | E5: Cahiers PS, MS, GS alignés
A6: Cycle 2 (CP, CE1, CE2) | B6: Programme du cycle 2 | C6: BO du 31/10/2024 | D6: Rentrée 2025 | E6: Livres CP, CE1, CE2 alignés
A7: CM1, CM2 | B7: Programmes 2025 | C7: Arrêté du 10/04/2025, BO n°16 du 17/04/2025 | D7: CM1 : rentrée 2025 ; CM2 : rentrée 2026 | E7: Livres CM1 et CM2 alignés
A8: Sixième | B8: Programme 2025 du cycle 3 | C8: BO n°16 du 17/04/2025 | D8: Rentrée 2025 | E8: Livre de 6e aligné
A9: Cycle 4 (5e, 4e, 3e) | B9: Programme de mathématiques du cycle 4 | C9: Arrêté du 18/02/2026, BO n°10 du 05/03/2026 | D9: 5e : 2026 ; 4e : 2027 ; 3e : 2028 | E9: 5e auditée ; éditions 4e 2027 et 3e 2028 livrées
A10: Brevet (DNB) | B10: Définition des épreuves | C10: Note de service du 11/09/2026 (NOR MENE2623228N), BO spécial n°4 du 17/09/2026 | D10: Session 2027 | E10: 3e actuelle ; la 3e 2028 suit ce format en attendant un texte pour 2029
A11: Seconde | B11: Programme de Seconde générale et technologique | C11: BO n°14 du 02/04/2026 (NOR MENE2602914A) | D11: Rentrée 2026 | E11: Livre audité et relivré
A12: Première spécialité | B12: Programme de spécialité + épreuve anticipée | C12: BO n°14 du 02/04/2026 (NOR MENE2602917A) ; note du 11/09/2026 (NOR MENE2622640N) | D12: Rentrée 2026 ; bac 2028 | E12: Livre audité et relivré
A13: Terminale spécialité | B13: Programme de spécialité + épreuve | C13: BO n°14 du 02/04/2026 (NOR MENE2602919A) ; note du 11/09/2026 (NOR MENE2622642N) | D13: Rentrée 2027 ; bac 2028 | E13: Édition 2027 livrée ; l’édition actuelle suit le programme 2019, valable en 2026-2027
A14: Physique-chimie Terminale | B14: Programme de spécialité + épreuve | C14: BO spécial n°8 du 25/07/2019 ; note du 11/09/2026 | D14: En vigueur ; session 2027 | E14: Livre terminé, livraison à finir
